[32m2024-04-04 22:38:46 -0500[0m - dagster - [34mDEBUG[0m - __ASSET_JOB - 0819191a-2dec-49cf-bede-f48da5048cb4 - 26467 - LOGS_CAPTURED - Started capturing logs in process (pid: 26467).
[32m2024-04-04 22:38:46 -0500[0m - dagster - [34mDEBUG[0m - __ASSET_JOB - 0819191a-2dec-49cf-bede-f48da5048cb4 - 26467 - splitWomanAndChildrenFromMen - STEP_START - Started execution of step "splitWomanAndChildrenFromMen".
[32m2024-04-04 22:38:46 -0500[0m - dagster - [34mERROR[0m - [31m__ASSET_JOB - 0819191a-2dec-49cf-bede-f48da5048cb4 - 26467 - splitWomanAndChildrenFromMen - STEP_FAILURE - Execution of step "splitWomanAndChildrenFromMen" failed.

dagster._core.errors.DagsterExecutionStepExecutionError: Error occurred while executing op "splitWomanAndChildrenFromMen"::

NameError: name 'df' is not defined

Stack Trace:
  File "/Users/fussy/miniconda3/envs/dag/lib/python3.12/site-packages/dagster/_core/execution/plan/utils.py", line 54, in op_execution_error_boundary
    yield
  File "/Users/fussy/miniconda3/envs/dag/lib/python3.12/site-packages/dagster/_utils/__init__.py", line 464, in iterate_with_context
    next_output = next(iterator)
                  ^^^^^^^^^^^^^^
  File "/Users/fussy/miniconda3/envs/dag/lib/python3.12/site-packages/dagster/_core/execution/plan/compute_generator.py", line 141, in _coerce_op_compute_fn_to_iterator
    result = invoke_compute_fn(
             ^^^^^^^^^^^^^^^^^^
  File "/Users/fussy/miniconda3/envs/dag/lib/python3.12/site-packages/dagster/_core/execution/plan/compute_generator.py", line 129, in invoke_compute_fn
    return fn(context, **args_to_pass) if context_arg_provided else fn(**args_to_pass)
           ^^^^^^^^^^^^^^^^^^^^^^^^^^^
  File "/Users/fussy/Desktop/317_Project_1/314Project1DAG/314Project1DAG/assets.py", line 24, in splitWomanAndChildrenFromMen
    "preview": MetadataValue.md(df.head().to_markdown()),
                                ^^
[0m
