[32m2024-04-04 23:07:24 -0500[0m - dagster - [34mDEBUG[0m - __ASSET_JOB - 9e913d6a-d175-482a-865d-d187672f7621 - 27143 - LOGS_CAPTURED - Started capturing logs in process (pid: 27143).
[32m2024-04-04 23:07:24 -0500[0m - dagster - [34mDEBUG[0m - __ASSET_JOB - 9e913d6a-d175-482a-865d-d187672f7621 - 27143 - sumAmenityCharges - STEP_START - Started execution of step "sumAmenityCharges".
[32m2024-04-04 23:07:24 -0500[0m - dagster - [34mERROR[0m - [31m__ASSET_JOB - 9e913d6a-d175-482a-865d-d187672f7621 - 27143 - sumAmenityCharges - STEP_FAILURE - Execution of step "sumAmenityCharges" failed.

dagster._core.errors.DagsterInvalidMetadata: Could not resolve the metadata value for "Survival Rate By Spender Category" to a known type. Its type was <class 'pandas.core.series.Series'>. Consider wrapping the value with the appropriate MetadataValue type.

Stack Trace:
  File "/Users/fussy/miniconda3/envs/dag/lib/python3.12/site-packages/dagster/_core/execution/plan/execute_plan.py", line 282, in dagster_event_sequence_for_step
    for step_event in check.generator(step_events):
  File "/Users/fussy/miniconda3/envs/dag/lib/python3.12/site-packages/dagster/_core/execution/plan/execute_step.py", line 521, in core_dagster_event_sequence_for_step
    for user_event in _step_output_error_checked_user_event_sequence(
  File "/Users/fussy/miniconda3/envs/dag/lib/python3.12/site-packages/dagster/_core/execution/plan/execute_step.py", line 202, in _step_output_error_checked_user_event_sequence
    for user_event in user_event_sequence:
  File "/Users/fussy/miniconda3/envs/dag/lib/python3.12/site-packages/dagster/_core/execution/plan/execute_step.py", line 101, in _process_asset_results_to_events
    yield from _process_user_event(step_context, user_event)
  File "/Users/fussy/miniconda3/envs/dag/lib/python3.12/site-packages/dagster/_core/execution/plan/execute_step.py", line 124, in _process_user_event
    yield Output(
          ^^^^^^^
  File "/Users/fussy/miniconda3/envs/dag/lib/python3.12/site-packages/dagster/_core/decorator_utils.py", line 203, in wrapped_with_pre_call_fn
    return fn(*args, **kwargs)
           ^^^^^^^^^^^^^^^^^^^
  File "/Users/fussy/miniconda3/envs/dag/lib/python3.12/site-packages/dagster/_core/definitions/events.py", line 103, in __init__
    self._metadata = normalize_metadata(
                     ^^^^^^^^^^^^^^^^^^^
  File "/Users/fussy/miniconda3/envs/dag/lib/python3.12/site-packages/dagster/_core/definitions/metadata/__init__.py", line 103, in normalize_metadata
    raise DagsterInvalidMetadata(

The above exception occurred during handling of the following exception:
dagster._core.errors.DagsterInvalidMetadata: Its type was <class 'pandas.core.series.Series'>. Consider wrapping the value with the appropriate MetadataValue type.

Stack Trace:
  File "/Users/fussy/miniconda3/envs/dag/lib/python3.12/site-packages/dagster/_core/definitions/metadata/__init__.py", line 89, in normalize_metadata
    normalized_value = normalize_metadata_value(v)
                       ^^^^^^^^^^^^^^^^^^^^^^^^^^^
  File "/Users/fussy/miniconda3/envs/dag/lib/python3.12/site-packages/dagster/_core/definitions/metadata/__init__.py", line 139, in normalize_metadata_value
    raise DagsterInvalidMetadata(
[0m
