[32m2024-04-24 15:58:31 -0500[0m - dagster - [34mDEBUG[0m - __ASSET_JOB - 27820c86-0f7b-4952-9ceb-d544912cb1d7 - 13036 - LOGS_CAPTURED - Started capturing logs in process (pid: 13036).
[32m2024-04-24 15:58:31 -0500[0m - dagster - [34mDEBUG[0m - __ASSET_JOB - 27820c86-0f7b-4952-9ceb-d544912cb1d7 - 13036 - splitCabin - STEP_START - Started execution of step "splitCabin".
[32m2024-04-24 15:58:31 -0500[0m - dagster - [34mERROR[0m - [31m__ASSET_JOB - 27820c86-0f7b-4952-9ceb-d544912cb1d7 - 13036 - splitCabin - STEP_FAILURE - Execution of step "splitCabin" failed.

dagster._core.errors.DagsterExecutionStepExecutionError: Error occurred while executing op "splitCabin"::

UnboundLocalError: local variable 'data' referenced before assignment

Stack Trace:
  File "/Users/qingtan/anaconda3/envs/cse217a/lib/python3.10/site-packages/dagster/_core/execution/plan/utils.py", line 54, in op_execution_error_boundary
    yield
  File "/Users/qingtan/anaconda3/envs/cse217a/lib/python3.10/site-packages/dagster/_utils/__init__.py", line 464, in iterate_with_context
    next_output = next(iterator)
  File "/Users/qingtan/anaconda3/envs/cse217a/lib/python3.10/site-packages/dagster/_core/execution/plan/compute_generator.py", line 141, in _coerce_op_compute_fn_to_iterator
    result = invoke_compute_fn(
  File "/Users/qingtan/anaconda3/envs/cse217a/lib/python3.10/site-packages/dagster/_core/execution/plan/compute_generator.py", line 129, in invoke_compute_fn
    return fn(context, **args_to_pass) if context_arg_provided else fn(**args_to_pass)
  File "/Users/qingtan/Desktop/CSE314A/314_Project_1/src/assets.py", line 25, in splitCabin
    data[['Deck', 'Num', 'Side']] = data['Cabin'].str.split('/', expand=True)
[0m
