[32m2024-04-24 17:34:26 -0500[0m - dagster - [34mDEBUG[0m - __ASSET_JOB - b8d29dd9-8222-48bb-880d-f3014eafd9f5 - 16642 - LOGS_CAPTURED - Started capturing logs in process (pid: 16642).
[32m2024-04-24 17:34:26 -0500[0m - dagster - [34mDEBUG[0m - __ASSET_JOB - b8d29dd9-8222-48bb-880d-f3014eafd9f5 - 16642 - splitWomanAndChildrenFromMen - STEP_START - Started execution of step "splitWomanAndChildrenFromMen".
[32m2024-04-24 17:34:27 -0500[0m - dagster - [34mERROR[0m - [31m__ASSET_JOB - b8d29dd9-8222-48bb-880d-f3014eafd9f5 - 16642 - splitWomanAndChildrenFromMen - STEP_FAILURE - Execution of step "splitWomanAndChildrenFromMen" failed.

dagster._core.errors.DagsterExecutionStepExecutionError: Error occurred while executing op "splitWomanAndChildrenFromMen"::

NameError: name 'num_survived_adults' is not defined. Did you mean: 'survived_adults'?

Stack Trace:
  File "/Users/fussy/miniconda3/envs/dag/lib/python3.12/site-packages/dagster/_core/execution/plan/utils.py", line 54, in op_execution_error_boundary
    yield
  File "/Users/fussy/miniconda3/envs/dag/lib/python3.12/site-packages/dagster/_utils/__init__.py", line 464, in iterate_with_context
    next_output = next(iterator)
                  ^^^^^^^^^^^^^^
  File "/Users/fussy/miniconda3/envs/dag/lib/python3.12/site-packages/dagster/_core/execution/plan/compute_generator.py", line 141, in _coerce_op_compute_fn_to_iterator
    result = invoke_compute_fn(
             ^^^^^^^^^^^^^^^^^^
  File "/Users/fussy/miniconda3/envs/dag/lib/python3.12/site-packages/dagster/_core/execution/plan/compute_generator.py", line 129, in invoke_compute_fn
    return fn(context, **args_to_pass) if context_arg_provided else fn(**args_to_pass)
           ^^^^^^^^^^^^^^^^^^^^^^^^^^^
  File "/Users/fussy/Desktop/317_Project_1/src/assets.py", line 119, in splitWomanAndChildrenFromMen
    plt.bar(positions_adults, [total_adults, num_survived_adults], bar_width, color='skyblue', label='Adults')
                                             ^^^^^^^^^^^^^^^^^^^
[0m
